Workbook
Name budget: 'Budget Dashboard'!$L1
Name budget_range: 'Budget Dashboard'!$Q1
Name budget_rank: 'Budget Dashboard'!$R1
Name comb_rank: 'Budget Dashboard'!$S1
Name comb_rank_norm: 'Budget Dashboard'!$U1
Name comb_rank_norm_run_range: 'Budget Dashboard'!$V1
Name comb_rank_range: 'Budget Dashboard'!$T1
Name comb_rank_unique: 'Budget Dashboard'!$W1
Name current_date: TODAY()
Name expenses_header_row: ROW(Expenses[[#Headers],[Expenses]])
Name expenses_max_row: MAX(ROW(Expenses[]))
Name expenses_min_row: MIN(ROW(Expenses[]))
Name expenses_total_row: ROW('Budget Planning'!$C$43)
Name header_row_id: 'Budget Dashboard'!$D1
Name income_header_row: ROW(Income[[#Headers],[Income]])
Name income_max_row: MAX(ROW(Income[]))
Name income_min_row: MIN(ROW(Income[]))
Name income_total_row: ROW('Budget Planning'!$C$21)
Name is_cat: 'Budget Dashboard'!$F1
Name is_empty: 'Budget Dashboard'!$H1
Name is_empty: 'Budget Planning'!$H1
Name is_header: 'Budget Dashboard'!$E1
Name is_header: 'Budget Planning'!$E1
Name is_total: 'Budget Dashboard'!$G1
Name is_total: 'Budget Dashboard'!$G1
Name item: 'Budget Dashboard'!$J1
Name out_budget: 'Budget Dashboard'!$AA1
Name out_percentage_completed: 'Budget Dashboard'!$AB1
Name out_tracked: 'Budget Dashboard'!$Z1
Name row_id: 'Budget Dashboard'!$C1
Name savings_header_row: ROW(Savings[[#Headers],[Savings]])
Name savings_max_row: MAX(ROW(Savings[]))
Name savings_min_row: MIN(ROW(Savings[]))
Name savings_total_row: ROW('Budget Planning'!$C$58)
Name selected_period: Calculation!$E$21:$E$21
Name selected_period_display: Calculation!$E$22:$E$22
Name selected_year: Calculation!$E$20:$E$20
Name shift_late_income_field: Settings!$E$15:$E$15
Name shift_late_income_starting_day: Settings!$E$15:$E$15
Name shift_late_income_status: Settings!$E$13:$E$13
Name sort_max_row: 'Budget Dashboard'!$N1
Name sort_min_row: 'Budget Dashboard'!$M1
Name starting_year: Settings!$E$6:$E$6
Name tracked: 'Budget Dashboard'!$K1
Name tracked_range: 'Budget Dashboard'!$O1
Name tracked_rank: 'Budget Dashboard'!$P1
Name type: 'Budget Dashboard'!$I1

Sheet Add-ons
B2: Things to Add: | C2: ✓
B3: Charts | C3: FALSE
B4: Debt Tracker | C4: FALSE
B5: Credit Card | C5: FALSE
B6: Average Daily Spend | C6: FALSE

Sheet Budget Planning
E5: {=starting_year} -> 2025 | S5: =E5+1 -> 2026 | AG5: =S5+1 -> 2027 | AU5: =AG5+1 -> 2028 | BI5: =AU5+1 -> 2029 | BW5: =BI5+1 -> 2030
E6: =IF(E7=0,"Jan ✓",E9) -> Jan ✓ | F6: =IF(F7=0,"Feb ✓",F9) -> Feb ✓ | G6: =IF(G7=0,"Mar ✓",G9) -> Mar ✓ | H6: =IF(H7=0,"Apr ✓",H9) -> Apr ✓ | I6: =IF(I7=0,"May ✓",I9) -> May ✓ | J6: =IF(J7=0,"Jun ✓",J9) -> Jun ✓ | K6: =IF(K7=0,"Jul ✓",K9) -> Jul ✓ | L6: =IF(L7=0,"Aug ✓",L9) -> Aug ✓ | M6: =IF(M7=0,"Sep ✓",M9) -> Sep ✓ | N6: =IF(N7=0,"Oct ✓",N9) -> Oct ✓ | O6: =IF(O7=0,"Nov ✓",O9) -> Nov ✓ | P6: =IF(P7=0,"Dec ✓",P9) -> Dec ✓ | Q6: =IF(Q7=0,"Total ✓","Total") -> Total ✓ | S6: =IF(S7=0,"Jan ✓",S9) -> Jan ✓ | T6: =IF(T7=0,"Feb ✓",T9) -> Feb ✓ | U6: =IF(U7=0,"Mar ✓",U9) -> 46082 | V6: =IF(V7=0,"Apr ✓",V9) -> 46113 | W6: =IF(W7=0,"May ✓",W9) -> 46143 | X6: =IF(X7=0,"Jun ✓",X9) -> 46174 | Y6: =IF(Y7=0,"Jul ✓",Y9) -> 46204 | Z6: =IF(Z7=0,"Aug ✓",Z9) -> 46235 | AA6: =IF(AA7=0,"Sep ✓",AA9) -> 46266 | AB6: =IF(AB7=0,"Oct ✓",AB9) -> 46296 | AC6: =IF(AC7=0,"Nov ✓",AC9) -> 46327 | AD6: =IF(AD7=0,"Dec ✓",AD9) -> 46357 | AE6: =IF(AE7=0,"Total ✓","Total") -> Total | AG6: =IF(AG7=0,"Jan ✓",AG9) -> 46388 | AH6: =IF(AH7=0,"Feb ✓",AH9) -> 46419 | AI6: =IF(AI7=0,"Mar ✓",AI9) -> 46447 | AJ6: =IF(AJ7=0,"Apr ✓",AJ9) -> 46478 | AK6: =IF(AK7=0,"May ✓",AK9) -> 46508 | AL6: =IF(AL7=0,"Jun ✓",AL9) -> 46539 | AM6: =IF(AM7=0,"Jul ✓",AM9) -> 46569 | AN6: =IF(AN7=0,"Aug ✓",AN9) -> 46600 | AO6: =IF(AO7=0,"Sep ✓",AO9) -> 46631 | AP6: =IF(AP7=0,"Oct ✓",AP9) -> 46661 | AQ6: =IF(AQ7=0,"Nov ✓",AQ9) -> 46692 | AR6: =IF(AR7=0,"Dec ✓",AR9) -> 46722 | AS6: =IF(AS7=0,"Total ✓","Total") -> Total | AU6: =IF(AU7=0,"Jan ✓",AU9) -> Jan ✓ | AV6: =IF(AV7=0,"Feb ✓",AV9) -> Feb ✓ | AW6: =IF(AW7=0,"Mar ✓",AW9) -> Mar ✓ | AX6: =IF(AX7=0,"Apr ✓",AX9) -> Apr ✓ | AY6: =IF(AY7=0,"May ✓",AY9) -> May ✓ | AZ6: =IF(AZ7=0,"Jun ✓",AZ9) -> Jun ✓ | BA6: =IF(BA7=0,"Jul ✓",BA9) -> Jul ✓ | BB6: =IF(BB7=0,"Aug ✓",BB9) -> Aug ✓ | BC6: =IF(BC7=0,"Sep ✓",BC9) -> Sep ✓ | BD6: =IF(BD7=0,"Oct ✓",BD9) -> Oct ✓ | BE6: =IF(BE7=0,"Nov ✓",BE9) -> Nov ✓ | BF6: =IF(BF7=0,"Dec ✓",BF9) -> Dec ✓ | BG6: =IF(BG7=0,"Total ✓","Total") -> Total ✓ | BI6: =IF(BI7=0,"Jan ✓",BI9) -> Jan ✓ | BJ6: =IF(BJ7=0,"Feb ✓",BJ9) -> Feb ✓ | BK6: =IF(BK7=0,"Mar ✓",BK9) -> Mar ✓ | BL6: =IF(BL7=0,"Apr ✓",BL9) -> Apr ✓ | BM6: =IF(BM7=0,"May ✓",BM9) -> May ✓ | BN6: =IF(BN7=0,"Jun ✓",BN9) -> Jun ✓ | BO6: =IF(BO7=0,"Jul ✓",BO9) -> Jul ✓ | BP6: =IF(BP7=0,"Aug ✓",BP9) -> Aug ✓ | BQ6: =IF(BQ7=0,"Sep ✓",BQ9) -> Sep ✓ | BR6: =IF(BR7=0,"Oct ✓",BR9) -> Oct ✓ | BS6: =IF(BS7=0,"Nov ✓",BS9) -> Nov ✓ | BT6: =IF(BT7=0,"Dec ✓",BT9) -> Dec ✓ | BU6: =IF(BU7=0,"Total ✓","Total") -> Total ✓ | BW6: =IF(BW7=0,"Jan ✓",BW9) -> Jan ✓ | BX6: =IF(BX7=0,"Feb ✓",BX9) -> Feb ✓ | BY6: =IF(BY7=0,"Mar ✓",BY9) -> Mar ✓ | BZ6: =IF(BZ7=0,"Apr ✓",BZ9) -> Apr ✓ | CA6: =IF(CA7=0,"May ✓",CA9) -> May ✓ | CB6: =IF(CB7=0,"Jun ✓",CB9) -> Jun ✓ | CC6: =IF(CC7=0,"Jul ✓",CC9) -> Jul ✓ | CD6: =IF(CD7=0,"Aug ✓",CD9) -> Aug ✓ | CE6: =IF(CE7=0,"Sep ✓",CE9) -> Sep ✓ | CF6: =IF(CF7=0,"Oct ✓",CF9) -> Oct ✓ | CG6: =IF(CG7=0,"Nov ✓",CG9) -> Nov ✓ | CH6: =IF(CH7=0,"Dec ✓",CH9) -> Dec ✓ | CI6: =IF(CI7=0,"Total ✓","Total") -> Total ✓
C7: To be allocated: | E7: =E21-(E43+E58) -> 0 | F7: =F21-(F43+F58) -> 0 | G7: =G21-(G43+G58) -> 0 | H7: =H21-(H43+H58) -> 0 | I7: =I21-(I43+I58) -> 0 | J7: =J21-(J43+J58) -> 0 | K7: =K21-(K43+K58) -> 0 | L7: =L21-(L43+L58) -> 0 | ... Q7: =Q21-(Q43+Q58) -> 0 | S7: =S21-(S43+S58) -> 0 | T7: =T21-(T43+T58) -> 0 | U7: =U21-(U43+U58) -> 288.39 | V7: =V21-(V43+V58) -> 188.39 | W7: =W21-(W43+W58) -> 188.39 | X7: =X21-(X43+X58) -> 188.39 | Y7: =Y21-(Y43+Y58) -> 218.39 | Z7: =Z21-(Z43+Z58) -> 218.39 | ... AE7: =AE21-(AE43+AE58) -> 2163.9 | AG7: =AG21-(AG43+AG58) -> 2537.33 | AH7: =AH21-(AH43+AH58) -> 2537.33 | AI7: =AI21-(AI43+AI58) -> 2537.33 | AJ7: =AJ21-(AJ43+AJ58) -> 2537.33 | AK7: =AK21-(AK43+AK58) -> 2537.33 | AL7: =AL21-(AL43+AL58) -> 2537.33 | AM7: =AM21-(AM43+AM58) -> 2537.33 | AN7: =AN21-(AN43+AN58) -> 2537.33 | ... AS7: =AS21-(AS43+AS58) -> 30447.96 | AU7: =AU21-(AU43+AU58) -> 0 | AV7: =AV21-(AV43+AV58) -> 0 | AW7: =AW21-(AW43+AW58) -> 0 | AX7: =AX21-(AX43+AX58) -> 0 | AY7: =AY21-(AY43+AY58) -> 0 | AZ7: =AZ21-(AZ43+AZ58) -> 0 | BA7: =BA21-(BA43+BA58) -> 0 | BB7: =BB21-(BB43+BB58) -> 0 | ... BG7: =BG21-(BG43+BG58) -> 0 | BI7: =BI21-(BI43+BI58) -> 0 | BJ7: =BJ21-(BJ43+BJ58) -> 0 | BK7: =BK21-(BK43+BK58) -> 0 | BL7: =BL21-(BL43+BL58) -> 0 | BM7: =BM21-(BM43+BM58) -> 0 | BN7: =BN21-(BN43+BN58) -> 0 | BO7: =BO21-(BO43+BO58) -> 0 | BP7: =BP21-(BP43+BP58) -> 0 | ... BU7: =BU21-(BU43+BU58) -> 0 | BW7: =BW21-(BW43+BW58) -> 0 | BX7: =BX21-(BX43+BX58) -> 0 | BY7: =BY21-(BY43+BY58) -> 0 | BZ7: =BZ21-(BZ43+BZ58) -> 0 | CA7: =CA21-(CA43+CA58) -> 0 | CB7: =CB21-(CB43+CB58) -> 0 | CC7: =CC21-(CC43+CC58) -> 0 | CD7: =CD21-(CD43+CD58) -> 0 | ... CI7: =CI21-(CI43+CI58) -> 0
C9: Income | E9: =DATE(E$5,1,1) -> 45658 | F9: =DATE(E$5,2,1) -> 45689 | G9: =DATE(E$5,3,1) -> 45717 | H9: =DATE(E$5,4,1) -> 45748 | I9: =DATE(E$5,5,1) -> 45778 | J9: =DATE(E$5,6,1) -> 45809 | K9: =DATE(E$5,7,1) -> 45839 | L9: =DATE(E$5,8,1) -> 45870 | M9: =DATE(E$5,9,1) -> 45901 | N9: =DATE(E$5,10,1) -> 45931 | O9: =DATE(E$5,11,1) -> 45962 | P9: =DATE(E$5,12,1) -> 45992 | Q9: =E$5 -> 2025 | S9: =DATE(S$5,1,1) -> 46023 | T9: =DATE(S$5,2,1) -> 46054 | U9: =DATE(S$5,3,1) -> 46082 | V9: =DATE(S$5,4,1) -> 46113 | W9: =DATE(S$5,5,1) -> 46143 | X9: =DATE(S$5,6,1) -> 46174 | Y9: =DATE(S$5,7,1) -> 46204 | Z9: =DATE(S$5,8,1) -> 46235 | AA9: =DATE(S$5,9,1) -> 46266 | AB9: =DATE(S$5,10,1) -> 46296 | AC9: =DATE(S$5,11,1) -> 46327 | AD9: =DATE(S$5,12,1) -> 46357 | AE9: =S$5 -> 2026 | AG9: =DATE(AG$5,1,1) -> 46388 | AH9: =DATE(AG$5,2,1) -> 46419 | AI9: =DATE(AG$5,3,1) -> 46447 | AJ9: =DATE(AG$5,4,1) -> 46478 | AK9: =DATE(AG$5,5,1) -> 46508 | AL9: =DATE(AG$5,6,1) -> 46539 | AM9: =DATE(AG$5,7,1) -> 46569 | AN9: =DATE(AG$5,8,1) -> 46600 | AO9: =DATE(AG$5,9,1) -> 46631 | AP9: =DATE(AG$5,10,1) -> 46661 | AQ9: =DATE(AG$5,11,1) -> 46692 | AR9: =DATE(AG$5,12,1) -> 46722 | AS9: =AG$5 -> 2027 | AU9: =DATE(AU$5,1,1) -> 46753 | AV9: =DATE(AU$5,2,1) -> 46784 | AW9: =DATE(AU$5,3,1) -> 46813 | AX9: =DATE(AU$5,4,1) -> 46844 | AY9: =DATE(AU$5,5,1) -> 46874 | AZ9: =DATE(AU$5,6,1) -> 46905 | BA9: =DATE(AU$5,7,1) -> 46935 | BB9: =DATE(AU$5,8,1) -> 46966 | BC9: =DATE(AU$5,9,1) -> 46997 | BD9: =DATE(AU$5,10,1) -> 47027 | BE9: =DATE(AU$5,11,1) -> 47058 | BF9: =DATE(AU$5,12,1) -> 47088 | BG9: =AU$5 -> 2028 | BI9: =DATE(BI$5,1,1) -> 47119 | BJ9: =DATE(BI$5,2,1) -> 47150 | BK9: =DATE(BI$5,3,1) -> 47178 | BL9: =DATE(BI$5,4,1) -> 47209 | BM9: =DATE(BI$5,5,1) -> 47239 | BN9: =DATE(BI$5,6,1) -> 47270 | BO9: =DATE(BI$5,7,1) -> 47300 | BP9: =DATE(BI$5,8,1) -> 47331 | BQ9: =DATE(BI$5,9,1) -> 47362 | BR9: =DATE(BI$5,10,1) -> 47392 | BS9: =DATE(BI$5,11,1) -> 47423 | BT9: =DATE(BI$5,12,1) -> 47453 | BU9: =BI$5 -> 2029 | BW9: =DATE(BW$5,1,1) -> 47484 | BX9: =DATE(BW$5,2,1) -> 47515 | BY9: =DATE(BW$5,3,1) -> 47543 | BZ9: =DATE(BW$5,4,1) -> 47574 | CA9: =DATE(BW$5,5,1) -> 47604 | CB9: =DATE(BW$5,6,1) -> 47635 | CC9: =DATE(BW$5,7,1) -> 47665 | CD9: =DATE(BW$5,8,1) -> 47696 | CE9: =DATE(BW$5,9,1) -> 47727 | CF9: =DATE(BW$5,10,1) -> 47757 | CG9: =DATE(BW$5,11,1) -> 47788 | CH9: =DATE(BW$5,12,1) -> 47818 | CI9: =BW$5 -> 2030
C10: Employment (Net) | M10: 4234 | N10: 4234 | O10: 4234 | P10: 4234 | Q10: =SUM(E10:P10) -> 16936 | S10: 5083.34 | T10: 5083.34 | U10: 5210.41 | V10: 5210.41 | W10: 5210.41 | X10: 5210.41 | Y10: 5210.41 | Z10: 5210.41 | AA10: 5210.41 | AB10: 5210.41 | AC10: 5210.41 | AD10: 5210.41 | AE10: =SUM(S10:AD10) -> 62270.78 | AG10: 5083.34 | AH10: 5083.34 | AI10: 5083.34 | AJ10: 5083.34 | AK10: 5083.34 | AL10: 5083.34 | AM10: 5083.34 | AN10: 5083.34 | AO10: 5083.34 | AP10: 5083.34 | AQ10: 5083.34 | AR10: 5083.34 | AS10: =SUM(AG10:AR10) -> 61000.08 | BG10: =SUM(AU10:BF10) -> 0 | BU10: =SUM(BI10:BT10) -> 0 | CI10: =SUM(BW10:CH10) -> 0
C11: Side Hustle (Net) | Q11: =SUM(E11:P11) -> 0 | AE11: =SUM(S11:AD11) -> 0 | AS11: =SUM(AG11:AR11) -> 0 | BG11: =SUM(AU11:BF11) -> 0 | BU11: =SUM(BI11:BT11) -> 0 | CI11: =SUM(BW11:CH11) -> 0
C12: Divedends | Q12: =SUM(E12:P12) -> 0 | AE12: =SUM(S12:AD12) -> 0 | AS12: =SUM(AG12:AR12) -> 0 | BG12: =SUM(AU12:BF12) -> 0 | BU12: =SUM(BI12:BT12) -> 0 | CI12: =SUM(BW12:CH12) -> 0
C13: Rollover | Q13: =SUM(E13:P13) -> 0 | V13: 1780 | AE13: =SUM(S13:AD13) -> 1780 | AS13: =SUM(AG13:AR13) -> 0 | BG13: =SUM(AU13:BF13) -> 0 | BU13: =SUM(BI13:BT13) -> 0 | CI13: =SUM(BW13:CH13) -> 0
C14: Misc. | Q14: =SUM(E14:P14) -> 0 | AE14: =SUM(S14:AD14) -> 0 | AS14: =SUM(AG14:AR14) -> 0 | BG14: =SUM(AU14:BF14) -> 0 | BU14: =SUM(BI14:BT14) -> 0 | CI14: =SUM(BW14:CH14) -> 0
C15: Enter Income Category... | Q15: =SUM(E15:P15) -> 0 | AE15: =SUM(S15:AD15) -> 0 | AS15: =SUM(AG15:AR15) -> 0 | BG15: =SUM(AU15:BF15) -> 0 | BU15: =SUM(BI15:BT15) -> 0 | CI15: =SUM(BW15:CH15) -> 0
C16: Enter Income Category... | Q16: =SUM(E16:P16) -> 0 | AE16: =SUM(S16:AD16) -> 0 | AS16: =SUM(AG16:AR16) -> 0 | BG16: =SUM(AU16:BF16) -> 0 | BU16: =SUM(BI16:BT16) -> 0 | CI16: =SUM(BW16:CH16) -> 0
C17: Enter Income Category... | Q17: =SUM(E17:P17) -> 0 | AE17: =SUM(S17:AD17) -> 0 | AS17: =SUM(AG17:AR17) -> 0 | BG17: =SUM(AU17:BF17) -> 0 | BU17: =SUM(BI17:BT17) -> 0 | CI17: =SUM(BW17:CH17) -> 0
C18: Enter Income Category... | Q18: =SUM(E18:P18) -> 0 | AE18: =SUM(S18:AD18) -> 0 | AS18: =SUM(AG18:AR18) -> 0 | BG18: =SUM(AU18:BF18) -> 0 | BU18: =SUM(BI18:BT18) -> 0 | CI18: =SUM(BW18:CH18) -> 0
C19: Enter Income Category... | Q19: =SUM(E19:P19) -> 0 | AE19: =SUM(S19:AD19) -> 0 | AS19: =SUM(AG19:AR19) -> 0 | BG19: =SUM(AU19:BF19) -> 0 | BU19: =SUM(BI19:BT19) -> 0 | CI19: =SUM(BW19:CH19) -> 0
C20: Enter Income Category... | Q20: =SUM(E20:P20) -> 0 | AE20: =SUM(S20:AD20) -> 0 | AS20: =SUM(AG20:AR20) -> 0 | BG20: =SUM(AU20:BF20) -> 0 | BU20: =SUM(BI20:BT20) -> 0 | CI20: =SUM(BW20:CH20) -> 0
C21: Total | E21: {=SUM(INDIRECT(ADDRESS(income_min_row,COLUMN()) & ":" & ADDRESS(income_max_row,COLUMN())))} -> 0 | F21: {=SUM(INDIRECT(ADDRESS(income_min_row,COLUMN()) & ":" & ADDRESS(income_max_row,COLUMN())))} -> 0 | G21: {=SUM(INDIRECT(ADDRESS(income_min_row,COLUMN()) & ":" & ADDRESS(income_max_row,COLUMN())))} -> 0 | H21: {=SUM(INDIRECT(ADDRESS(income_min_row,COLUMN()) & ":" & ADDRESS(income_max_row,COLUMN())))} -> 0 | I21: {=SUM(INDIRECT(ADDRESS(income_min_row,COLUMN()) & ":" & ADDRESS(income_max_row,COLUMN())))} -> 0 | J21: {=SUM(INDIRECT(ADDRESS(income_min_row,COLUMN()) & ":" & ADDRESS(income_max_row,COLUMN())))} -> 0 | K21: {=SUM(INDIRECT(ADDRESS(income_min_row,COLUMN()) & ":" & ADDRESS(income_max_row,COLUMN())))} -> 0 | L21: {=SUM(INDIRECT(ADDRESS(income_min_row,COLUMN()) & ":" & ADDRESS(income_max_row,COLUMN())))} -> 0 | ... Q21: {=SUM(INDIRECT(ADDRESS(income_min_row,COLUMN()) & ":" & ADDRESS(income_max_row,COLUMN())))} -> 16936 | S21: {=SUM(INDIRECT(ADDRESS(income_min_row,COLUMN()) & ":" & ADDRESS(income_max_row,COLUMN())))} -> 5083.34 | T21: {=SUM(INDIRECT(ADDRESS(income_min_row,COLUMN()) & ":" & ADDRESS(income_max_row,COLUMN())))} -> 5083.34 | U21: {=SUM(INDIRECT(ADDRESS(income_min_row,COLUMN()) & ":" & ADDRESS(income_max_row,COLUMN())))} -> 5210.41 | V21: {=SUM(INDIRECT(ADDRESS(income_min_row,COLUMN()) & ":" & ADDRESS(income_max_row,COLUMN())))} -> 6990.41 | W21: {=SUM(INDIRECT(ADDRESS(income_min_row,COLUMN()) & ":" & ADDRESS(income_max_row,COLUMN())))} -> 5210.41 | X21: {=SUM(INDIRECT(ADDRESS(income_min_row,COLUMN()) & ":" & ADDRESS(income_max_row,COLUMN())))} -> 5210.41 | Y21: {=SUM(INDIRECT(ADDRESS(income_min_row,COLUMN()) & ":" & ADDRESS(income_max_row,COLUMN())))} -> 5210.41 | Z21: {=SUM(INDIRECT(ADDRESS(income_min_row,COLUMN()) & ":" & ADDRESS(income_max_row,COLUMN())))} -> 5210.41 | ... AE21: {=SUM(INDIRECT(ADDRESS(income_min_row,COLUMN()) & ":" & ADDRESS(income_max_row,COLUMN())))} -> 64050.78 | AG21: {=SUM(INDIRECT(ADDRESS(income_min_row,COLUMN()) & ":" & ADDRESS(income_max_row,COLUMN())))} -> 5083.34 | AH21: {=SUM(INDIRECT(ADDRESS(income_min_row,COLUMN()) & ":" & ADDRESS(income_max_row,COLUMN())))} -> 5083.34 | AI21: {=SUM(INDIRECT(ADDRESS(income_min_row,COLUMN()) & ":" & ADDRESS(income_max_row,COLUMN())))} -> 5083.34 | AJ21: {=SUM(INDIRECT(ADDRESS(income_min_row,COLUMN()) & ":" & ADDRESS(income_max_row,COLUMN())))} -> 5083.34 | AK21: {=SUM(INDIRECT(ADDRESS(income_min_row,COLUMN()) & ":" & ADDRESS(income_max_row,COLUMN())))} -> 5083.34 | AL21: {=SUM(INDIRECT(ADDRESS(income_min_row,COLUMN()) & ":" & ADDRESS(income_max_row,COLUMN())))} -> 5083.34 | AM21: {=SUM(INDIRECT(ADDRESS(income_min_row,COLUMN()) & ":" & ADDRESS(income_max_row,COLUMN())))} -> 5083.34 | AN21: {=SUM(INDIRECT(ADDRESS(income_min_row,COLUMN()) & ":" & ADDRESS(income_max_row,COLUMN())))} -> 5083.34 | ... AS21: {=SUM(INDIRECT(ADDRESS(income_min_row,COLUMN()) & ":" & ADDRESS(income_max_row,COLUMN())))} -> 61000.08 | AU21: {=SUM(INDIRECT(ADDRESS(income_min_row,COLUMN()) & ":" & ADDRESS(income_max_row,COLUMN())))} -> 0 | AV21: {=SUM(INDIRECT(ADDRESS(income_min_row,COLUMN()) & ":" & ADDRESS(income_max_row,COLUMN())))} -> 0 | AW21: {=SUM(INDIRECT(ADDRESS(income_min_row,COLUMN()) & ":" & ADDRESS(income_max_row,COLUMN())))} -> 0 | AX21: {=SUM(INDIRECT(ADDRESS(income_min_row,COLUMN()) & ":" & ADDRESS(income_max_row,COLUMN())))} -> 0 | AY21: {=SUM(INDIRECT(ADDRESS(income_min_row,COLUMN()) & ":" & ADDRESS(income_max_row,COLUMN())))} -> 0 | AZ21: {=SUM(INDIRECT(ADDRESS(income_min_row,COLUMN()) & ":" & ADDRESS(income_max_row,COLUMN())))} -> 0 | BA21: {=SUM(INDIRECT(ADDRESS(income_min_row,COLUMN()) & ":" & ADDRESS(income_max_row,COLUMN())))} -> 0 | BB21: {=SUM(INDIRECT(ADDRESS(income_min_row,COLUMN()) & ":" & ADDRESS(income_max_row,COLUMN())))} -> 0 | ... BG21: {=SUM(INDIRECT(ADDRESS(income_min_row,COLUMN()) & ":" & ADDRESS(income_max_row,COLUMN())))} -> 0 | BI21: {=SUM(INDIRECT(ADDRESS(income_min_row,COLUMN()) & ":" & ADDRESS(income_max_row,COLUMN())))} -> 0 | BJ21: {=SUM(INDIRECT(ADDRESS(income_min_row,COLUMN()) & ":" & ADDRESS(income_max_row,COLUMN())))} -> 0 | BK21: {=SUM(INDIRECT(ADDRESS(income_min_row,COLUMN()) & ":" & ADDRESS(income_max_row,COLUMN())))} -> 0 | BL21: {=SUM(INDIRECT(ADDRESS(income_min_row,COLUMN()) & ":" & ADDRESS(income_max_row,COLUMN())))} -> 0 | BM21: {=SUM(INDIRECT(ADDRESS(income_min_row,COLUMN()) & ":" & ADDRESS(income_max_row,COLUMN())))} -> 0 | BN21: {=SUM(INDIRECT(ADDRESS(income_min_row,COLUMN()) & ":" & ADDRESS(income_max_row,COLUMN())))} -> 0 | BO21: {=SUM(INDIRECT(ADDRESS(income_min_row,COLUMN()) & ":" & ADDRESS(income_max_row,COLUMN())))} -> 0 | BP21: {=SUM(INDIRECT(ADDRESS(income_min_row,COLUMN()) & ":" & ADDRESS(income_max_row,COLUMN())))} -> 0 | ... BU21: {=SUM(INDIRECT(ADDRESS(income_min_row,COLUMN()) & ":" & ADDRESS(income_max_row,COLUMN())))} -> 0 | BW21: {=SUM(INDIRECT(ADDRESS(income_min_row,COLUMN()) & ":" & ADDRESS(income_max_row,COLUMN())))} -> 0 | BX21: {=SUM(INDIRECT(ADDRESS(income_min_row,COLUMN()) & ":" & ADDRESS(income_max_row,COLUMN())))} -> 0 | BY21: {=SUM(INDIRECT(ADDRESS(income_min_row,COLUMN()) & ":" & ADDRESS(income_max_row,COLUMN())))} -> 0 | BZ21: {=SUM(INDIRECT(ADDRESS(income_min_row,COLUMN()) & ":" & ADDRESS(income_max_row,COLUMN())))} -> 0 | CA21: {=SUM(INDIRECT(ADDRESS(income_min_row,COLUMN()) & ":" & ADDRESS(income_max_row,COLUMN())))} -> 0 | CB21: {=SUM(INDIRECT(ADDRESS(income_min_row,COLUMN()) & ":" & ADDRESS(income_max_row,COLUMN())))} -> 0 | CC21: {=SUM(INDIRECT(ADDRESS(income_min_row,COLUMN()) & ":" & ADDRESS(income_max_row,COLUMN())))} -> 0 | CD21: {=SUM(INDIRECT(ADDRESS(income_min_row,COLUMN()) & ":" & ADDRESS(income_max_row,COLUMN())))} -> 0 | ... CI21: {=SUM(INDIRECT(ADDRESS(income_min_row,COLUMN()) & ":" & ADDRESS(income_max_row,COLUMN())))} -> 0
C23: Expenses | E23: =DATE(E$5,1,1) -> 45658 | F23: =DATE(E$5,2,1) -> 45689 | G23: =DATE(E$5,3,1) -> 45717 | H23: =DATE(E$5,4,1) -> 45748 | I23: =DATE(E$5,5,1) -> 45778 | J23: =DATE(E$5,6,1) -> 45809 | K23: =DATE(E$5,7,1) -> 45839 | L23: =DATE(E$5,8,1) -> 45870 | M23: =DATE(E$5,9,1) -> 45901 | N23: =DATE(E$5,10,1) -> 45931 | O23: =DATE(E$5,11,1) -> 45962 | P23: =DATE(E$5,12,1) -> 45992 | Q23: =E$5 -> 2025 | S23: =DATE(S$5,1,1) -> 46023 | T23: =DATE(S$5,2,1) -> 46054 | U23: =DATE(S$5,3,1) -> 46082 | V23: =DATE(S$5,4,1) -> 46113 | W23: =DATE(S$5,5,1) -> 46143 | X23: =DATE(S$5,6,1) -> 46174 | Y23: =DATE(S$5,7,1) -> 46204 | Z23: =DATE(S$5,8,1) -> 46235 | AA23: =DATE(S$5,9,1) -> 46266 | AB23: =DATE(S$5,10,1) -> 46296 | AC23: =DATE(S$5,11,1) -> 46327 | AD23: =DATE(S$5,12,1) -> 46357 | AE23: =S$5 -> 2026 | AG23: =DATE(AG$5,1,1) -> 46388 | AH23: =DATE(AG$5,2,1) -> 46419 | AI23: =DATE(AG$5,3,1) -> 46447 | AJ23: =DATE(AG$5,4,1) -> 46478 | AK23: =DATE(AG$5,5,1) -> 46508 | AL23: =DATE(AG$5,6,1) -> 46539 | AM23: =DATE(AG$5,7,1) -> 46569 | AN23: =DATE(AG$5,8,1) -> 46600 | AO23: =DATE(AG$5,9,1) -> 46631 | AP23: =DATE(AG$5,10,1) -> 46661 | AQ23: =DATE(AG$5,11,1) -> 46692 | AR23: =DATE(AG$5,12,1) -> 46722 | AS23: =AG$5 -> 2027 | AU23: =DATE(AU$5,1,1) -> 46753 | AV23: =DATE(AU$5,2,1) -> 46784 | AW23: =DATE(AU$5,3,1) -> 46813 | AX23: =DATE(AU$5,4,1) -> 46844 | AY23: =DATE(AU$5,5,1) -> 46874 | AZ23: =DATE(AU$5,6,1) -> 46905 | BA23: =DATE(AU$5,7,1) -> 46935 | BB23: =DATE(AU$5,8,1) -> 46966 | BC23: =DATE(AU$5,9,1) -> 46997 | BD23: =DATE(AU$5,10,1) -> 47027 | BE23: =DATE(AU$5,11,1) -> 47058 | BF23: =DATE(AU$5,12,1) -> 47088 | BG23: =AU$5 -> 2028 | BI23: =DATE(BI$5,1,1) -> 47119 | BJ23: =DATE(BI$5,2,1) -> 47150 | BK23: =DATE(BI$5,3,1) -> 47178 | BL23: =DATE(BI$5,4,1) -> 47209 | BM23: =DATE(BI$5,5,1) -> 47239 | BN23: =DATE(BI$5,6,1) -> 47270 | BO23: =DATE(BI$5,7,1) -> 47300 | BP23: =DATE(BI$5,8,1) -> 47331 | BQ23: =DATE(BI$5,9,1) -> 47362 | BR23: =DATE(BI$5,10,1) -> 47392 | BS23: =DATE(BI$5,11,1) -> 47423 | BT23: =DATE(BI$5,12,1) -> 47453 | BU23: =BI$5 -> 2029 | BW23: =DATE(BW$5,1,1) -> 47484 | BX23: =DATE(BW$5,2,1) -> 47515 | BY23: =DATE(BW$5,3,1) -> 47543 | BZ23: =DATE(BW$5,4,1) -> 47574 | CA23: =DATE(BW$5,5,1) -> 47604 | CB23: =DATE(BW$5,6,1) -> 47635 | CC23: =DATE(BW$5,7,1) -> 47665 | CD23: =DATE(BW$5,8,1) -> 47696 | CE23: =DATE(BW$5,9,1) -> 47727 | CF23: =DATE(BW$5,10,1) -> 47757 | CG23: =DATE(BW$5,11,1) -> 47788 | CH23: =DATE(BW$5,12,1) -> 47818 | CI23: =BW$5 -> 2030
C24: Housing | M24: 1280 | N24: 1280 | O24: 1280 | P24: 1280 | Q24: =SUM(E24:P24) -> 5120 | S24: 1280 | T24: 1280 | U24: 1280 | V24: 1280 | W24: 1280 | X24: 1280 | Y24: 1280 | Z24: 1280 | AA24: 1280 | AB24: 1280 | AC24: 1280 | AD24: 1280 | AE24: =SUM(S24:AD24) -> 15360 | AG24: 1280 | AH24: 1280 | AI24: 1280 | AJ24: 1280 | AK24: 1280 | AL24: 1280 | AM24: 1280 | AN24: 1280 | AO24: 1280 | AP24: 1280 | AQ24: 1280 | AR24: 1280 | AS24: =SUM(AG24:AR24) -> 15360 | BG24: =SUM(AU24:BF24) -> 0 | BU24: =SUM(BI24:BT24) -> 0 | CI24: =SUM(BW24:CH24) -> 0
C25: Taxes | Q25: =SUM(E25:P25) -> 0 | S25: 747.02 | T25: 796 | U25: 747.02 | V25: 747.02 | W25: 747.02 | X25: 747.02 | Y25: 747.02 | Z25: 747.02 | AA25: 747.02 | AB25: 747.02 | AC25: 747.02 | AD25: 747.02 | AE25: =SUM(S25:AD25) -> 9013.22 | AS25: =SUM(AG25:AR25) -> 0 | BG25: =SUM(AU25:BF25) -> 0 | BU25: =SUM(BI25:BT25) -> 0 | CI25: =SUM(BW25:CH25) -> 0
C26: Benifits | P26: 102.38 | Q26: =SUM(E26:P26) -> 102.38 | S26: 204.76 | T26: 204.76 | U26: 204.76 | V26: 204.76 | W26: 204.76 | X26: 204.76 | Y26: 204.76 | Z26: 204.76 | AA26: 204.76 | AB26: 204.76 | AC26: 204.76 | AD26: 204.76 | AE26: =SUM(S26:AD26) -> 2457.12
C27: Car Payments | M27: 212 | N27: 212 | O27: 212 | P27: 370 | Q27: =SUM(E27:P27) -> 1006 | S27: 400 | T27: 250 | U27: 250 | V27: =1780+250 -> 2030 | W27: 250 | X27: 250 | Y27: 250 | Z27: 250 | AA27: 250 | AB27: 250 | AC27: 250 | AD27: 250 | AE27: =SUM(S27:AD27) -> 4930 | AG27: 250 | AH27: 250 | AI27: 250 | AJ27: 250 | AK27: 250 | AL27: 250 | AM27: 250 | AN27: 250 | AO27: 250 | AP27: 250 | AQ27: 250 | AR27: 250 | AS27: =SUM(AG27:AR27) -> 3000 | BG27: =SUM(AU27:BF27) -> 0 | BU27: =SUM(BI27:BT27) -> 0 | CI27: =SUM(BW27:CH27) -> 0
C28: Car Insurance | M28: 117.25 | N28: 117.25 | O28: 117.25 | P28: 117.25 | Q28: =SUM(E28:P28) -> 469 | S28: 161.02 | T28: 404.4 | U28: 404.4 | V28: 404.4 | W28: 404.4 | X28: 404.4 | Y28: 180 | Z28: 180 | AA28: 180 | AB28: 180 | AC28: 180 | AD28: 180 | AE28: =SUM(S28:AD28) -> 3263.02
C29: Car Warranty | T29: 151.67 | U29: 151.67 | V29: 151.67 | W29: 151.67 | X29: 151.67 | Y29: 151.67 | Z29: 151.67 | AA29: 151.67 | AB29: 151.67 | AC29: 151.67 | AD29: 151.67 | AE29: =SUM(S29:AD29) -> 1668.37
C30: Medical | AE30: =SUM(S30:AD30) -> 0
C31: Utilities | M31: 150 | N31: 150 | O31: 150 | P31: 150 | Q31: =SUM(E31:P31) -> 600 | S31: 100 | T31: 150 | U31: 200 | V31: 200 | W31: 200 | X31: 200 | Y31: 200 | Z31: 200 | AA31: 200 | AB31: 200 | AC31: 200 | AD31: 200 | AE31: =SUM(S31:AD31) -> 2250 | AS31: =SUM(AG31:AR31) -> 0 | BG31: =SUM(AU31:BF31) -> 0 | BU31: =SUM(BI31:BT31) -> 0 | CI31: =SUM(BW31:CH31) -> 0
C32: Groceries | M32: 200 | N32: 200 | O32: 200 | P32: 300 | Q32: =SUM(E32:P32) -> 900 | S32: 100 | T32: 200 | U32: 200 | V32: 200 | W32: 200 | X32: 200 | Y32: 200 | Z32: 200 | AA32: 200 | AB32: 200 | AC32: 200 | AD32: 200 | AE32: =SUM(S32:AD32) -> 2300 | AS32: =SUM(AG32:AR32) -> 0 | BG32: =SUM(AU32:BF32) -> 0 | BU32: =SUM(BI32:BT32) -> 0 | CI32: =SUM(BW32:CH32) -> 0
C33: Travel | T33: 300 | V33: 50 | W33: 50 | X33: 50 | Y33: 24.4 | Z33: 24.4 | AA33: 24.4 | AB33: 24.4 | AC33: 24.4 | AD33: 24.4 | AE33: =SUM(S33:AD33) -> 596.4
C34: Transportation | M34: 100 | N34: 100 | O34: 100 | P34: 0 | Q34: =SUM(E34:P34) -> 300 | S34: 150 | T34: 80 | U34: 80 | V34: 80 | W34: 80 | X34: 80 | Y34: 80 | Z34: 80 | AA34: 80 | AB34: 80 | AC34: 80 | AD34: 80 | AE34: =SUM(S34:AD34) -> 1030 | AS34: =SUM(AG34:AR34) -> 0 | BG34: =SUM(AU34:BF34) -> 0 | BU34: =SUM(BI34:BT34) -> 0 | CI34: =SUM(BW34:CH34) -> 0
C35: Clothing | M35: 100 | N35: 100 | O35: 100 | P35: 0 | Q35: =SUM(E35:P35) -> 300 | S35: 0 | T35: 50 | V35: 50 | W35: 50 | X35: 50 | Y35: 50 | Z35: 50 | AA35: 50 | AB35: 50 | AC35: 50 | AD35: 50 | AE35: =SUM(S35:AD35) -> 500 | AS35: =SUM(AG35:AR35) -> 0 | BG35: =SUM(AU35:BF35) -> 0 | BU35: =SUM(BI35:BT35) -> 0 | CI35: =SUM(BW35:CH35) -> 0
C36: Food | M36: 200 | N36: 200 | O36: 200 | P36: 100 | Q36: =SUM(E36:P36) -> 700 | S36: 300 | T36: 100 | U36: 100 | V36: 100 | W36: 100 | X36: 100 | Y36: 120 | Z36: 120 | AA36: 120 | AB36: 120 | AC36: 120 | AD36: 120 | AE36: =SUM(S36:AD36) -> 1520 | AS36: =SUM(AG36:AR36) -> 0 | BG36: =SUM(AU36:BF36) -> 0 | BU36: =SUM(BI36:BT36) -> 0 | CI36: =SUM(BW36:CH36) -> 0
C37: Media/Entertainment | M37: 200 | N37: 200 | O37: 200 | P37: 50 | Q37: =SUM(E37:P37) -> 650 | S37: 100 | T37: 70 | U37: 100 | V37: 100 | W37: 100 | X37: 100 | Y37: 100 | Z37: 100 | AA37: 100 | AB37: 100 | AC37: 100 | AD37: 100 | AE37: =SUM(S37:AD37) -> 1170 | AS37: =SUM(AG37:AR37) -> 0 | BG37: =SUM(AU37:BF37) -> 0 | BU37: =SUM(BI37:BT37) -> 0 | CI37: =SUM(BW37:CH37) -> 0
C38: Fun/Activities | M38: 300 | N38: 300 | O38: 300 | P38: 300 | Q38: =SUM(E38:P38) -> 1200 | S38: 600 | T38: 549.35 | U38: 300 | V38: 300 | W38: 300 | X38: 300 | Y38: 300 | Z38: 300 | AA38: 300 | AB38: 300 | AC38: 300 | AD38: 300 | AE38: =SUM(S38:AD38) -> 4149.35 | AS38: =SUM(AG38:AR38) -> 0 | BG38: =SUM(AU38:BF38) -> 0 | BU38: =SUM(BI38:BT38) -> 0 | CI38: =SUM(BW38:CH38) -> 0
C39: Body Care & Medicine | M39: 100 | N39: 100 | O39: 100 | P39: 50 | Q39: =SUM(E39:P39) -> 350 | S39: 0 | T39: 30 | AE39: =SUM(S39:AD39) -> 30 | AS39: =SUM(AG39:AR39) -> 0 | BG39: =SUM(AU39:BF39) -> 0 | BU39: =SUM(BI39:BT39) -> 0 | CI39: =SUM(BW39:CH39) -> 0
C40: Gifts | S40: 50 | T40: 200 | AE40: =SUM(S40:AD40) -> 250
C41: Charity | M41: 24.75 | N41: 24.75 | O41: 24.75 | P41: 33.12 | Q41: =SUM(E41:P41) -> 107.37 | S41: 20 | T41: 12.993 | AE41: =SUM(S41:AD41) -> 32.993 | AS41: =SUM(AG41:AR41) -> 0 | BG41: =SUM(AU41:BF41) -> 0 | BU41: =SUM(BI41:BT41) -> 0 | CI41: =SUM(BW41:CH41) -> 0
C42: Enter Expenses Category... | Q42: =SUM(E42:P42) -> 0 | AE42: =SUM(S42:AD42) -> 0 | AS42: =SUM(AG42:AR42) -> 0 | BG42: =SUM(AU42:BF42) -> 0 | BU42: =SUM(BI42:BT42) -> 0 | CI42: =SUM(BW42:CH42) -> 0
C43: Total | E43: {=SUM(INDIRECT(ADDRESS(expenses_min_row,COLUMN()) & ":" & ADDRESS(expenses_max_row,COLUMN())))} -> 0 | F43: {=SUM(INDIRECT(ADDRESS(expenses_min_row,COLUMN()) & ":" & ADDRESS(expenses_max_row,COLUMN())))} -> 0 | G43: {=SUM(INDIRECT(ADDRESS(expenses_min_row,COLUMN()) & ":" & ADDRESS(expenses_max_row,COLUMN())))} -> 0 | H43: {=SUM(INDIRECT(ADDRESS(expenses_min_row,COLUMN()) & ":" & ADDRESS(expenses_max_row,COLUMN())))} -> 0 | I43: {=SUM(INDIRECT(ADDRESS(expenses_min_row,COLUMN()) & ":" & ADDRESS(expenses_max_row,COLUMN())))} -> 0 | J43: {=SUM(INDIRECT(ADDRESS(expenses_min_row,COLUMN()) & ":" & ADDRESS(expenses_max_row,COLUMN())))} -> 0 | K43: {=SUM(INDIRECT(ADDRESS(expenses_min_row,COLUMN()) & ":" & ADDRESS(expenses_max_row,COLUMN())))} -> 0 | L43: {=SUM(INDIRECT(ADDRESS(expenses_min_row,COLUMN()) & ":" & ADDRESS(expenses_max_row,COLUMN())))} -> 0 | ... Q43: {=SUM(INDIRECT(ADDRESS(expenses_min_row,COLUMN()) & ":" & ADDRESS(expenses_max_row,COLUMN())))} -> 11804.75 | S43: {=SUM(INDIRECT(ADDRESS(expenses_min_row,COLUMN()) & ":" & ADDRESS(expenses_max_row,COLUMN())))} -> 4212.8 | T43: {=SUM(INDIRECT(ADDRESS(expenses_min_row,COLUMN()) & ":" & ADDRESS(expenses_max_row,COLUMN())))} -> 4829.173 | U43: {=SUM(INDIRECT(ADDRESS(expenses_min_row,COLUMN()) & ":" & ADDRESS(expenses_max_row,COLUMN())))} -> 4017.85 | V43: {=SUM(INDIRECT(ADDRESS(expenses_min_row,COLUMN()) & ":" & ADDRESS(expenses_max_row,COLUMN())))} -> 5897.85 | W43: {=SUM(INDIRECT(ADDRESS(expenses_min_row,COLUMN()) & ":" & ADDRESS(expenses_max_row,COLUMN())))} -> 4117.85 | X43: {=SUM(INDIRECT(ADDRESS(expenses_min_row,COLUMN()) & ":" & ADDRESS(expenses_max_row,COLUMN())))} -> 4117.85 | Y43: {=SUM(INDIRECT(ADDRESS(expenses_min_row,COLUMN()) & ":" & ADDRESS(expenses_max_row,COLUMN())))} -> 3887.85 | Z43: {=SUM(INDIRECT(ADDRESS(expenses_min_row,COLUMN()) & ":" & ADDRESS(expenses_max_row,COLUMN())))} -> 3887.85 | ... AE43: {=SUM(INDIRECT(ADDRESS(expenses_min_row,COLUMN()) & ":" & ADDRESS(expenses_max_row,COLUMN())))} -> 50520.473 | AG43: {=SUM(INDIRECT(ADDRESS(expenses_min_row,COLUMN()) & ":" & ADDRESS(expenses_max_row,COLUMN())))} -> 1530 | AH43: {=SUM(INDIRECT(ADDRESS(expenses_min_row,COLUMN()) & ":" & ADDRESS(expenses_max_row,COLUMN())))} -> 1530 | AI43: {=SUM(INDIRECT(ADDRESS(expenses_min_row,COLUMN()) & ":" & ADDRESS(expenses_max_row,COLUMN())))} -> 1530 | AJ43: {=SUM(INDIRECT(ADDRESS(expenses_min_row,COLUMN()) & ":" & ADDRESS(expenses_max_row,COLUMN())))} -> 1530 | AK43: {=SUM(INDIRECT(ADDRESS(expenses_min_row,COLUMN()) & ":" & ADDRESS(expenses_max_row,COLUMN())))} -> 1530 | AL43: {=SUM(INDIRECT(ADDRESS(expenses_min_row,COLUMN()) & ":" & ADDRESS(expenses_max_row,COLUMN())))} -> 1530 | AM43: {=SUM(INDIRECT(ADDRESS(expenses_min_row,COLUMN()) & ":" & ADDRESS(expenses_max_row,COLUMN())))} -> 1530 | AN43: {=SUM(INDIRECT(ADDRESS(expenses_min_row,COLUMN()) & ":" & ADDRESS(expenses_max_row,COLUMN())))} -> 1530 | ... AS43: {=SUM(INDIRECT(ADDRESS(expenses_min_row,COLUMN()) & ":" & ADDRESS(expenses_max_row,COLUMN())))} -> 18360 | AU43: {=SUM(INDIRECT(ADDRESS(expenses_min_row,COLUMN()) & ":" & ADDRESS(expenses_max_row,COLUMN())))} -> 0 | AV43: {=SUM(INDIRECT(ADDRESS(expenses_min_row,COLUMN()) & ":" & ADDRESS(expenses_max_row,COLUMN())))} -> 0 | AW43: {=SUM(INDIRECT(ADDRESS(expenses_min_row,COLUMN()) & ":" & ADDRESS(expenses_max_row,COLUMN())))} -> 0 | AX43: {=SUM(INDIRECT(ADDRESS(expenses_min_row,COLUMN()) & ":" & ADDRESS(expenses_max_row,COLUMN())))} -> 0 | AY43: {=SUM(INDIRECT(ADDRESS(expenses_min_row,COLUMN()) & ":" & ADDRESS(expenses_max_row,COLUMN())))} -> 0 | AZ43: {=SUM(INDIRECT(ADDRESS(expenses_min_row,COLUMN()) & ":" & ADDRESS(expenses_max_row,COLUMN())))} -> 0 | BA43: {=SUM(INDIRECT(ADDRESS(expenses_min_row,COLUMN()) & ":" & ADDRESS(expenses_max_row,COLUMN())))} -> 0 | BB43: {=SUM(INDIRECT(ADDRESS(expenses_min_row,COLUMN()) & ":" & ADDRESS(expenses_max_row,COLUMN())))} -> 0 | ... BG43: {=SUM(INDIRECT(ADDRESS(expenses_min_row,COLUMN()) & ":" & ADDRESS(expenses_max_row,COLUMN())))} -> 0 | BI43: {=SUM(INDIRECT(ADDRESS(expenses_min_row,COLUMN()) & ":" & ADDRESS(expenses_max_row,COLUMN())))} -> 0 | BJ43: {=SUM(INDIRECT(ADDRESS(expenses_min_row,COLUMN()) & ":" & ADDRESS(expenses_max_row,COLUMN())))} -> 0 | BK43: {=SUM(INDIRECT(ADDRESS(expenses_min_row,COLUMN()) & ":" & ADDRESS(expenses_max_row,COLUMN())))} -> 0 | BL43: {=SUM(INDIRECT(ADDRESS(expenses_min_row,COLUMN()) & ":" & ADDRESS(expenses_max_row,COLUMN())))} -> 0 | BM43: {=SUM(INDIRECT(ADDRESS(expenses_min_row,COLUMN()) & ":" & ADDRESS(expenses_max_row,COLUMN())))} -> 0 | BN43: {=SUM(INDIRECT(ADDRESS(expenses_min_row,COLUMN()) & ":" & ADDRESS(expenses_max_row,COLUMN())))} -> 0 | BO43: {=SUM(INDIRECT(ADDRESS(expenses_min_row,COLUMN()) & ":" & ADDRESS(expenses_max_row,COLUMN())))} -> 0 | BP43: {=SUM(INDIRECT(ADDRESS(expenses_min_row,COLUMN()) & ":" & ADDRESS(expenses_max_row,COLUMN())))} -> 0 | ... BU43: {=SUM(INDIRECT(ADDRESS(expenses_min_row,COLUMN()) & ":" & ADDRESS(expenses_max_row,COLUMN())))} -> 0 | BW43: {=SUM(INDIRECT(ADDRESS(expenses_min_row,COLUMN()) & ":" & ADDRESS(expenses_max_row,COLUMN())))} -> 0 | BX43: {=SUM(INDIRECT(ADDRESS(expenses_min_row,COLUMN()) & ":" & ADDRESS(expenses_max_row,COLUMN())))} -> 0 | BY43: {=SUM(INDIRECT(ADDRESS(expenses_min_row,COLUMN()) & ":" & ADDRESS(expenses_max_row,COLUMN())))} -> 0 | BZ43: {=SUM(INDIRECT(ADDRESS(expenses_min_row,COLUMN()) & ":" & ADDRESS(expenses_max_row,COLUMN())))} -> 0 | CA43: {=SUM(INDIRECT(ADDRESS(expenses_min_row,COLUMN()) & ":" & ADDRESS(expenses_max_row,COLUMN())))} -> 0 | CB43: {=SUM(INDIRECT(ADDRESS(expenses_min_row,COLUMN()) & ":" & ADDRESS(expenses_max_row,COLUMN())))} -> 0 | CC43: {=SUM(INDIRECT(ADDRESS(expenses_min_row,COLUMN()) & ":" & ADDRESS(expenses_max_row,COLUMN())))} -> 0 | CD43: {=SUM(INDIRECT(ADDRESS(expenses_min_row,COLUMN()) & ":" & ADDRESS(expenses_max_row,COLUMN())))} -> 0 | ... CI43: {=SUM(INDIRECT(ADDRESS(expenses_min_row,COLUMN()) & ":" & ADDRESS(expenses_max_row,COLUMN())))} -> 0
C45: Savings | E45: =DATE(E$5,1,1) -> 45658 | F45: =DATE(E$5,2,1) -> 45689 | G45: =DATE(E$5,3,1) -> 45717 | H45: =DATE(E$5,4,1) -> 45748 | I45: =DATE(E$5,5,1) -> 45778 | J45: =DATE(E$5,6,1) -> 45809 | K45: =DATE(E$5,7,1) -> 45839 | L45: =DATE(E$5,8,1) -> 45870 | M45: =DATE(E$5,9,1) -> 45901 | N45: =DATE(E$5,10,1) -> 45931 | O45: =DATE(E$5,11,1) -> 45962 | P45: =DATE(E$5,12,1) -> 45992 | Q45: =E$5 -> 2025 | S45: =DATE(S$5,1,1) -> 46023 | T45: =DATE(S$5,2,1) -> 46054 | U45: =DATE(S$5,3,1) -> 46082 | V45: =DATE(S$5,4,1) -> 46113 | W45: =DATE(S$5,5,1) -> 46143 | X45: =DATE(S$5,6,1) -> 46174 | Y45: =DATE(S$5,7,1) -> 46204 | Z45: =DATE(S$5,8,1) -> 46235 | AA45: =DATE(S$5,9,1) -> 46266 | AB45: =DATE(S$5,10,1) -> 46296 | AC45: =DATE(S$5,11,1) -> 46327 | AD45: =DATE(S$5,12,1) -> 46357 | AE45: =S$5 -> 2026 | AG45: =DATE(AG$5,1,1) -> 46388 | AH45: =DATE(AG$5,2,1) -> 46419 | AI45: =DATE(AG$5,3,1) -> 46447 | AJ45: =DATE(AG$5,4,1) -> 46478 | AK45: =DATE(AG$5,5,1) -> 46508 | AL45: =DATE(AG$5,6,1) -> 46539 | AM45: =DATE(AG$5,7,1) -> 46569 | AN45: =DATE(AG$5,8,1) -> 46600 | AO45: =DATE(AG$5,9,1) -> 46631 | AP45: =DATE(AG$5,10,1) -> 46661 | AQ45: =DATE(AG$5,11,1) -> 46692 | AR45: =DATE(AG$5,12,1) -> 46722 | AS45: =AG$5 -> 2027 | AU45: =DATE(AU$5,1,1) -> 46753 | AV45: =DATE(AU$5,2,1) -> 46784 | AW45: =DATE(AU$5,3,1) -> 46813 | AX45: =DATE(AU$5,4,1) -> 46844 | AY45: =DATE(AU$5,5,1) -> 46874 | AZ45: =DATE(AU$5,6,1) -> 46905 | BA45: =DATE(AU$5,7,1) -> 46935 | BB45: =DATE(AU$5,8,1) -> 46966 | BC45: =DATE(AU$5,9,1) -> 46997 | BD45: =DATE(AU$5,10,1) -> 47027 | BE45: =DATE(AU$5,11,1) -> 47058 | BF45: =DATE(AU$5,12,1) -> 47088 | BG45: =AU$5 -> 2028 | BI45: =DATE(BI$5,1,1) -> 47119 | BJ45: =DATE(BI$5,2,1) -> 47150 | BK45: =DATE(BI$5,3,1) -> 47178 | BL45: =DATE(BI$5,4,1) -> 47209 | BM45: =DATE(BI$5,5,1) -> 47239 | BN45: =DATE(BI$5,6,1) -> 47270 | BO45: =DATE(BI$5,7,1) -> 47300 | BP45: =DATE(BI$5,8,1) -> 47331 | BQ45: =DATE(BI$5,9,1) -> 47362 | BR45: =DATE(BI$5,10,1) -> 47392 | BS45: =DATE(BI$5,11,1) -> 47423 | BT45: =DATE(BI$5,12,1) -> 47453 | BU45: =BI$5 -> 2029 | BW45: =DATE(BW$5,1,1) -> 47484 | BX45: =DATE(BW$5,2,1) -> 47515 | BY45: =DATE(BW$5,3,1) -> 47543 | BZ45: =DATE(BW$5,4,1) -> 47574 | CA45: =DATE(BW$5,5,1) -> 47604 | CB45: =DATE(BW$5,6,1) -> 47635 | CC45: =DATE(BW$5,7,1) -> 47665 | CD45: =DATE(BW$5,8,1) -> 47696 | CE45: =DATE(BW$5,9,1) -> 47727 | CF45: =DATE(BW$5,10,1) -> 47757 | CG45: =DATE(BW$5,11,1) -> 47788 | CH45: =DATE(BW$5,12,1) -> 47818 | CI45: =BW$5 -> 2030
C46: Emergency Fund | M46: 500 | N46: 500 | O46: 500 | P46: 1000 | Q46: =SUM(E46:P46) -> 2500 | S46: 100 | U46: 400 | V46: 400 | W46: 400 | X46: 400 | Y46: 500 | Z46: 500 | AA46: 500 | AB46: 500 | AC46: 500 | AD46: 500 | AE46: =SUM(S46:AD46) -> 4700 | AG46: 253.5 | AH46: 253.5 | AI46: 253.5 | AJ46: 253.5 | AK46: 253.5 | AL46: 253.5 | AM46: 253.5 | AN46: 253.5 | AO46: 253.5 | AP46: 253.5 | AQ46: 253.5 | AR46: 253.5 | AS46: =SUM(AG46:AR46) -> 3042 | BG46: =SUM(AU46:BF46) -> 0 | BU46: =SUM(BI46:BT46) -> 0 | CI46: =SUM(BW46:CH46) -> 0
C47: 401K | M47: 500 | N47: 500 | O47: 500 | P47: 381.25 | Q47: =SUM(E47:P47) -> 1881.25 | S47: 762.5 | T47: 254.167 | U47: 254.17 | V47: 254.17 | W47: 254.17 | X47: 254.17 | Y47: 254.17 | Z47: 254.17 | AA47: 254.17 | AB47: 254.17 | AC47: 254.17 | AD47: 254.17 | AE47: =SUM(S47:AD47) -> 3558.367 | AG47: 254.17 | AH47: 254.17 | AI47: 254.17 | AJ47: 254.17 | AK47: 254.17 | AL47: 254.17 | AM47: 254.17 | AN47: 254.17 | AO47: 254.17 | AP47: 254.17 | AQ47: 254.17 | AR47: 254.17 | AS47: =SUM(AG47:AR47) -> 3050.04 | BG47: =SUM(AU47:BF47) -> 0 | BU47: =SUM(BI47:BT47) -> 0 | CI47: =SUM(BW47:CH47) -> 0
...

Sheet Budget Tracking
A1: Budget Tracking
B6: Date of Today | C6: Date of Last Record
B8: =Calculation!E8 -> 46072 | C8: =Calculation!E9 -> 46071 | D8: =Calculation!E10 -> (1 days ago) | E8: =COUNT(Tracking[Date]) -> 122
B11: Date | C11: Type | D11: Category | E11: Amount | F11: Details | G11: Balance | H11: Effective Date
B12: 46006 | C12: Savings | D12: 401K | E12: 381.25 | G12: {=SUMPRODUCT(Tracking[Amount],--(Tracking[Date]<=Tracking[[#This Row],[Date]]),(Tracking[Type]<>"Income")*(-1) + (Tracking[Type]="Income"))} -> -381.25 | H12: {=IF(AND(Tracking[[#This Row],[Type]]="Income",shift_late_income_status="Active",DAY(Tracking[[#This Row],[Date]])>=shift_late_income_starting_day),DATE(YEAR(Tracking[[#This Row],[Date]]),MONTH(Tracking[[#This Row],[Date]])+1,1),Tracking[[#This Row],[Date]])} -> 46006
B13: 46021 | C13: Income | D13: Employment (Net) | E13: 2541.67 | G13: {=SUMPRODUCT(Tracking[Amount],--(Tracking[Date]<=Tracking[[#This Row],[Date]]),(Tracking[Type]<>"Income")*(-1) + (Tracking[Type]="Income"))} -> 2160.42 | H13: {=IF(AND(Tracking[[#This Row],[Type]]="Income",shift_late_income_status="Active",DAY(Tracking[[#This Row],[Date]])>=shift_late_income_starting_day),DATE(YEAR(Tracking[[#This Row],[Date]]),MONTH(Tracking[[#This Row],[Date]])+1,1),Tracking[[#This Row],[Date]])} -> 46023
B14: 46023 | C14: Income | D14: Rollover | E14: 1790.41 | F14: This is because I have started tracking my budget on Jan 26 so this all the money I had before handin my bank account already | G14: {=SUMPRODUCT(Tracking[Amount],--(Tracking[Date]<=Tracking[[#This Row],[Date]]),(Tracking[Type]<>"Income")*(-1) + (Tracking[Type]="Income"))} -> 415.71 | H14: {=IF(AND(Tracking[[#This Row],[Type]]="Income",shift_late_income_status="Active",DAY(Tracking[[#This Row],[Date]])>=shift_late_income_starting_day),DATE(YEAR(Tracking[[#This Row],[Date]]),MONTH(Tracking[[#This Row],[Date]])+1,1),Tracking[[#This Row],[Date]])} -> 46023
B15: 46023 | C15: Expenses | D15: Benifits | E15: 102.38 | G15: {=SUMPRODUCT(Tracking[Amount],--(Tracking[Date]<=Tracking[[#This Row],[Date]]),(Tracking[Type]<>"Income")*(-1) + (Tracking[Type]="Income"))} -> 415.71 | H15: {=IF(AND(Tracking[[#This Row],[Type]]="Income",shift_late_income_status="Active",DAY(Tracking[[#This Row],[Date]])>=shift_late_income_starting_day),DATE(YEAR(Tracking[[#This Row],[Date]]),MONTH(Tracking[[#This Row],[Date]])+1,1),Tracking[[#This Row],[Date]])} -> 46023
B16: 46023 | C16: Expenses | D16: Taxes | E16: 373.51 | G16: {=SUMPRODUCT(Tracking[Amount],--(Tracking[Date]<=Tracking[[#This Row],[Date]]),(Tracking[Type]<>"Income")*(-1) + (Tracking[Type]="Income"))} -> 415.71 | H16: {=IF(AND(Tracking[[#This Row],[Type]]="Income",shift_late_income_status="Active",DAY(Tracking[[#This Row],[Date]])>=shift_late_income_starting_day),DATE(YEAR(Tracking[[#This Row],[Date]]),MONTH(Tracking[[#This Row],[Date]])+1,1),Tracking[[#This Row],[Date]])} -> 46023
B17: 46023 | C17: Expenses | D17: Utilities | E17: 31.64 | F17: Gas | G17: {=SUMPRODUCT(Tracking[Amount],--(Tracking[Date]<=Tracking[[#This Row],[Date]]),(Tracking[Type]<>"Income")*(-1) + (Tracking[Type]="Income"))} -> 415.71 | H17: {=IF(AND(Tracking[[#This Row],[Type]]="Income",shift_late_income_status="Active",DAY(Tracking[[#This Row],[Date]])>=shift_late_income_starting_day),DATE(YEAR(Tracking[[#This Row],[Date]]),MONTH(Tracking[[#This Row],[Date]])+1,1),Tracking[[#This Row],[Date]])} -> 46023
B18: 46023 | C18: Expenses | D18: Housing | E18: 1280 | G18: {=SUMPRODUCT(Tracking[Amount],--(Tracking[Date]<=Tracking[[#This Row],[Date]]),(Tracking[Type]<>"Income")*(-1) + (Tracking[Type]="Income"))} -> 415.71 | H18: {=IF(AND(Tracking[[#This Row],[Type]]="Income",shift_late_income_status="Active",DAY(Tracking[[#This Row],[Date]])>=shift_late_income_starting_day),DATE(YEAR(Tracking[[#This Row],[Date]]),MONTH(Tracking[[#This Row],[Date]])+1,1),Tracking[[#This Row],[Date]])} -> 46023
B19: 46023 | C19: Expenses | D19: Fun/Activities | E19: 418.02 | F19: Luxor Hotel for Aryan on New Years | G19: {=SUMPRODUCT(Tracking[Amount],--(Tracking[Date]<=Tracking[[#This Row],[Date]]),(Tracking[Type]<>"Income")*(-1) + (Tracking[Type]="Income"))} -> 415.71 | H19: {=IF(AND(Tracking[[#This Row],[Type]]="Income",shift_late_income_status="Active",DAY(Tracking[[#This Row],[Date]])>=shift_late_income_starting_day),DATE(YEAR(Tracking[[#This Row],[Date]]),MONTH(Tracking[[#This Row],[Date]])+1,1),Tracking[[#This Row],[Date]])} -> 46023
B20: 46023 | C20: Expenses | D20: Fun/Activities | E20: 52.27 | F20: Luxor Expenses | G20: {=SUMPRODUCT(Tracking[Amount],--(Tracking[Date]<=Tracking[[#This Row],[Date]]),(Tracking[Type]<>"Income")*(-1) + (Tracking[Type]="Income"))} -> 415.71 | H20: {=IF(AND(Tracking[[#This Row],[Type]]="Income",shift_late_income_status="Active",DAY(Tracking[[#This Row],[Date]])>=shift_late_income_starting_day),DATE(YEAR(Tracking[[#This Row],[Date]]),MONTH(Tracking[[#This Row],[Date]])+1,1),Tracking[[#This Row],[Date]])} -> 46023
B21: 46023 | C21: Expenses | D21: Food | E21: 35.03 | F21: Starbucks at the Luxor | G21: {=SUMPRODUCT(Tracking[Amount],--(Tracking[Date]<=Tracking[[#This Row],[Date]]),(Tracking[Type]<>"Income")*(-1) + (Tracking[Type]="Income"))} -> 415.71 | H21: {=IF(AND(Tracking[[#This Row],[Type]]="Income",shift_late_income_status="Active",DAY(Tracking[[#This Row],[Date]])>=shift_late_income_starting_day),DATE(YEAR(Tracking[[#This Row],[Date]]),MONTH(Tracking[[#This Row],[Date]])+1,1),Tracking[[#This Row],[Date]])} -> 46023
B22: 46023 | C22: Savings | D22: Roth IRA | E22: 680 | G22: {=SUMPRODUCT(Tracking[Amount],--(Tracking[Date]<=Tracking[[#This Row],[Date]]),(Tracking[Type]<>"Income")*(-1) + (Tracking[Type]="Income"))} -> 415.71 | H22: {=IF(AND(Tracking[[#This Row],[Type]]="Income",shift_late_income_status="Active",DAY(Tracking[[#This Row],[Date]])>=shift_late_income_starting_day),DATE(YEAR(Tracking[[#This Row],[Date]]),MONTH(Tracking[[#This Row],[Date]])+1,1),Tracking[[#This Row],[Date]])} -> 46023
B23: 46023 | C23: Savings | D23: 401K | E23: 381.25 | G23: {=SUMPRODUCT(Tracking[Amount],--(Tracking[Date]<=Tracking[[#This Row],[Date]]),(Tracking[Type]<>"Income")*(-1) + (Tracking[Type]="Income"))} -> 415.71 | H23: {=IF(AND(Tracking[[#This Row],[Type]]="Income",shift_late_income_status="Active",DAY(Tracking[[#This Row],[Date]])>=shift_late_income_starting_day),DATE(YEAR(Tracking[[#This Row],[Date]]),MONTH(Tracking[[#This Row],[Date]])+1,1),Tracking[[#This Row],[Date]])} -> 46023
B24: 46023 | C24: Expenses | D24: Car Insurance | E24: 161.02 | G24: {=SUMPRODUCT(Tracking[Amount],--(Tracking[Date]<=Tracking[[#This Row],[Date]]),(Tracking[Type]<>"Income")*(-1) + (Tracking[Type]="Income"))} -> 415.71 | H24: {=IF(AND(Tracking[[#This Row],[Type]]="Income",shift_late_income_status="Active",DAY(Tracking[[#This Row],[Date]])>=shift_late_income_starting_day),DATE(YEAR(Tracking[[#This Row],[Date]]),MONTH(Tracking[[#This Row],[Date]])+1,1),Tracking[[#This Row],[Date]])} -> 46023
B25: 46023 | C25: Expenses | D25: Fun/Activities | E25: 20 | F25: Excalibur Parking | G25: {=SUMPRODUCT(Tracking[Amount],--(Tracking[Date]<=Tracking[[#This Row],[Date]]),(Tracking[Type]<>"Income")*(-1) + (Tracking[Type]="Income"))} -> 415.71 | H25: {=IF(AND(Tracking[[#This Row],[Type]]="Income",shift_late_income_status="Active",DAY(Tracking[[#This Row],[Date]])>=shift_late_income_starting_day),DATE(YEAR(Tracking[[#This Row],[Date]]),MONTH(Tracking[[#This Row],[Date]])+1,1),Tracking[[#This Row],[Date]])} -> 46023
B26: 46024 | C26: Expenses | D26: Media/Entertainment | E26: 11.99 | F26: Spotify | G26: {=SUMPRODUCT(Tracking[Amount],--(Tracking[Date]<=Tracking[[#This Row],[Date]]),(Tracking[Type]<>"Income")*(-1) + (Tracking[Type]="Income"))} -> 357.45 | H26: {=IF(AND(Tracking[[#This Row],[Type]]="Income",shift_late_income_status="Active",DAY(Tracking[[#This Row],[Date]])>=shift_late_income_starting_day),DATE(YEAR(Tracking[[#This Row],[Date]]),MONTH(Tracking[[#This Row],[Date]])+1,1),Tracking[[#This Row],[Date]])} -> 46024
B27: 46024 | C27: Expenses | D27: Groceries | E27: 1.94 | F27: Wet Wipes | G27: {=SUMPRODUCT(Tracking[Amount],--(Tracking[Date]<=Tracking[[#This Row],[Date]]),(Tracking[Type]<>"Income")*(-1) + (Tracking[Type]="Income"))} -> 357.45 | H27: {=IF(AND(Tracking[[#This Row],[Type]]="Income",shift_late_income_status="Active",DAY(Tracking[[#This Row],[Date]])>=shift_late_income_starting_day),DATE(YEAR(Tracking[[#This Row],[Date]]),MONTH(Tracking[[#This Row],[Date]])+1,1),Tracking[[#This Row],[Date]])} -> 46024
B28: 46024 | C28: Expenses | D28: Food | E28: 20 | G28: {=SUMPRODUCT(Tracking[Amount],--(Tracking[Date]<=Tracking[[#This Row],[Date]]),(Tracking[Type]<>"Income")*(-1) + (Tracking[Type]="Income"))} -> 357.45 | H28: {=IF(AND(Tracking[[#This Row],[Type]]="Income",shift_late_income_status="Active",DAY(Tracking[[#This Row],[Date]])>=shift_late_income_starting_day),DATE(YEAR(Tracking[[#This Row],[Date]]),MONTH(Tracking[[#This Row],[Date]])+1,1),Tracking[[#This Row],[Date]])} -> 46024
B29: 46024 | C29: Expenses | D29: Food | E29: 17.84 | F29: Snacks | G29: {=SUMPRODUCT(Tracking[Amount],--(Tracking[Date]<=Tracking[[#This Row],[Date]]),(Tracking[Type]<>"Income")*(-1) + (Tracking[Type]="Income"))} -> 357.45 | H29: {=IF(AND(Tracking[[#This Row],[Type]]="Income",shift_late_income_status="Active",DAY(Tracking[[#This Row],[Date]])>=shift_late_income_starting_day),DATE(YEAR(Tracking[[#This Row],[Date]]),MONTH(Tracking[[#This Row],[Date]])+1,1),Tracking[[#This Row],[Date]])} -> 46024
B30: 46024 | C30: Expenses | D30: Food | E30: 6.49 | F30: Rice | G30: {=SUMPRODUCT(Tracking[Amount],--(Tracking[Date]<=Tracking[[#This Row],[Date]]),(Tracking[Type]<>"Income")*(-1) + (Tracking[Type]="Income"))} -> 357.45 | H30: {=IF(AND(Tracking[[#This Row],[Type]]="Income",shift_late_income_status="Active",DAY(Tracking[[#This Row],[Date]])>=shift_late_income_starting_day),DATE(YEAR(Tracking[[#This Row],[Date]]),MONTH(Tracking[[#This Row],[Date]])+1,1),Tracking[[#This Row],[Date]])} -> 46024
B31: 46025 | C31: Expenses | D31: Food | E31: 20.27 | F31: Taco Stand | G31: {=SUMPRODUCT(Tracking[Amount],--(Tracking[Date]<=Tracking[[#This Row],[Date]]),(Tracking[Type]<>"Income")*(-1) + (Tracking[Type]="Income"))} -> 259.73 | H31: {=IF(AND(Tracking[[#This Row],[Type]]="Income",shift_late_income_status="Active",DAY(Tracking[[#This Row],[Date]])>=shift_late_income_starting_day),DATE(YEAR(Tracking[[#This Row],[Date]]),MONTH(Tracking[[#This Row],[Date]])+1,1),Tracking[[#This Row],[Date]])} -> 46025
B32: 46025 | C32: Expenses | D32: Fun/Activities | E32: 55 | F32: Batting Cage | G32: {=SUMPRODUCT(Tracking[Amount],--(Tracking[Date]<=Tracking[[#This Row],[Date]]),(Tracking[Type]<>"Income")*(-1) + (Tracking[Type]="Income"))} -> 259.73 | H32: {=IF(AND(Tracking[[#This Row],[Type]]="Income",shift_late_income_status="Active",DAY(Tracking[[#This Row],[Date]])>=shift_late_income_starting_day),DATE(YEAR(Tracking[[#This Row],[Date]]),MONTH(Tracking[[#This Row],[Date]])+1,1),Tracking[[#This Row],[Date]])} -> 46025
B33: 46025 | C33: Expenses | D33: Food | E33: 22.45 | F33: Lemongrass Thai Food | G33: {=SUMPRODUCT(Tracking[Amount],--(Tracking[Date]<=Tracking[[#This Row],[Date]]),(Tracking[Type]<>"Income")*(-1) + (Tracking[Type]="Income"))} -> 259.73 | H33: {=IF(AND(Tracking[[#This Row],[Type]]="Income",shift_late_income_status="Active",DAY(Tracking[[#This Row],[Date]])>=shift_late_income_starting_day),DATE(YEAR(Tracking[[#This Row],[Date]]),MONTH(Tracking[[#This Row],[Date]])+1,1),Tracking[[#This Row],[Date]])} -> 46025
B34: 46026 | C34: Expenses | D34: Transportation | E34: 10 | F34: Fremont Parking | G34: {=SUMPRODUCT(Tracking[Amount],--(Tracking[Date]<=Tracking[[#This Row],[Date]]),(Tracking[Type]<>"Income")*(-1) + (Tracking[Type]="Income"))} -> 212.24 | H34: {=IF(AND(Tracking[[#This Row],[Type]]="Income",shift_late_income_status="Active",DAY(Tracking[[#This Row],[Date]])>=shift_late_income_starting_day),DATE(YEAR(Tracking[[#This Row],[Date]]),MONTH(Tracking[[#This Row],[Date]])+1,1),Tracking[[#This Row],[Date]])} -> 46026
B35: 46026 | C35: Expenses | D35: Media/Entertainment | E35: 9.99 | F35: Playstation + | G35: {=SUMPRODUCT(Tracking[Amount],--(Tracking[Date]<=Tracking[[#This Row],[Date]]),(Tracking[Type]<>"Income")*(-1) + (Tracking[Type]="Income"))} -> 212.24 | H35: {=IF(AND(Tracking[[#This Row],[Type]]="Income",shift_late_income_status="Active",DAY(Tracking[[#This Row],[Date]])>=shift_late_income_starting_day),DATE(YEAR(Tracking[[#This Row],[Date]]),MONTH(Tracking[[#This Row],[Date]])+1,1),Tracking[[#This Row],[Date]])} -> 46026
B36: 46026 | C36: Expenses | D36: Fun/Activities | E36: 27.5 | F36: Chicken & Pickle | G36: {=SUMPRODUCT(Tracking[Amount],--(Tracking[Date]<=Tracking[[#This Row],[Date]]),(Tracking[Type]<>"Income")*(-1) + (Tracking[Type]="Income"))} -> 212.24 | H36: {=IF(AND(Tracking[[#This Row],[Type]]="Income",shift_late_income_status="Active",DAY(Tracking[[#This Row],[Date]])>=shift_late_income_starting_day),DATE(YEAR(Tracking[[#This Row],[Date]]),MONTH(Tracking[[#This Row],[Date]])+1,1),Tracking[[#This Row],[Date]])} -> 46026
B37: 46027 | C37: Expenses | D37: Food | E37: 26.05 | F37: Shawarma Paradise | G37: {=SUMPRODUCT(Tracking[Amount],--(Tracking[Date]<=Tracking[[#This Row],[Date]]),(Tracking[Type]<>"Income")*(-1) + (Tracking[Type]="Income"))} -> 186.19 | H37: {=IF(AND(Tracking[[#This Row],[Type]]="Income",shift_late_income_status="Active",DAY(Tracking[[#This Row],[Date]])>=shift_late_income_starting_day),DATE(YEAR(Tracking[[#This Row],[Date]]),MONTH(Tracking[[#This Row],[Date]])+1,1),Tracking[[#This Row],[Date]])} -> 46027
B38: 46028 | C38: Expenses | D38: Media/Entertainment | E38: 7.49 | F38: Amazon Prime | G38: {=SUMPRODUCT(Tracking[Amount],--(Tracking[Date]<=Tracking[[#This Row],[Date]]),(Tracking[Type]<>"Income")*(-1) + (Tracking[Type]="Income"))} -> 158.64 | H38: {=IF(AND(Tracking[[#This Row],[Type]]="Income",shift_late_income_status="Active",DAY(Tracking[[#This Row],[Date]])>=shift_late_income_starting_day),DATE(YEAR(Tracking[[#This Row],[Date]]),MONTH(Tracking[[#This Row],[Date]])+1,1),Tracking[[#This Row],[Date]])} -> 46028
B39: 46028 | C39: Income | D39: Divedends | E39: 31.86 | F39: Extra Robin Hood Money | G39: {=SUMPRODUCT(Tracking[Amount],--(Tracking[Date]<=Tracking[[#This Row],[Date]]),(Tracking[Type]<>"Income")*(-1) + (Tracking[Type]="Income"))} -> 158.64 | H39: {=IF(AND(Tracking[[#This Row],[Type]]="Income",shift_late_income_status="Active",DAY(Tracking[[#This Row],[Date]])>=shift_late_income_starting_day),DATE(YEAR(Tracking[[#This Row],[Date]]),MONTH(Tracking[[#This Row],[Date]])+1,1),Tracking[[#This Row],[Date]])} -> 46028
B40: 46028 | C40: Expenses | D40: Fun/Activities | E40: 66 | F40: Bowling | G40: {=SUMPRODUCT(Tracking[Amount],--(Tracking[Date]<=Tracking[[#This Row],[Date]]),(Tracking[Type]<>"Income")*(-1) + (Tracking[Type]="Income"))} -> 158.64 | H40: {=IF(AND(Tracking[[#This Row],[Type]]="Income",shift_late_income_status="Active",DAY(Tracking[[#This Row],[Date]])>=shift_late_income_starting_day),DATE(YEAR(Tracking[[#This Row],[Date]]),MONTH(Tracking[[#This Row],[Date]])+1,1),Tracking[[#This Row],[Date]])} -> 46028
... B47: 46036 | C47: Expenses | D47: Utilities | E47: 0 | F47: Karen Cleaning | G47: {=SUMPRODUCT(Tracking[Amount],--(Tracking[Date]<=Tracking[[#This Row],[Date]]),(Tracking[Type]<>"Income")*(-1) + (Tracking[Type]="Income"))} -> 80.05 | H47: {=IF(AND(Tracking[[#This Row],[Type]]="Income",shift_late_income_status="Active",DAY(Tracking[[#This Row],[Date]])>=shift_late_income_starting_day),DATE(YEAR(Tracking[[#This Row],[Date]]),MONTH(Tracking[[#This Row],[Date]])+1,1),Tracking[[#This Row],[Date]])} -> 46036
B48: 46037 | C48: Income | D48: Employment (Net) | E48: 2541.67 | G48: {=SUMPRODUCT(Tracking[Amount],--(Tracking[Date]<=Tracking[[#This Row],[Date]]),(Tracking[Type]<>"Income")*(-1) + (Tracking[Type]="Income"))} -> 1371.9 | H48: {=IF(AND(Tracking[[#This Row],[Type]]="Income",shift_late_income_status="Active",DAY(Tracking[[#This Row],[Date]])>=shift_late_income_starting_day),DATE(YEAR(Tracking[[#This Row],[Date]]),MONTH(Tracking[[#This Row],[Date]])+1,1),Tracking[[#This Row],[Date]])} -> 46037
B49: 46037 | C49: Expenses | D49: Food | E49: 0 | F49: China a go go | G49: {=SUMPRODUCT(Tracking[Amount],--(Tracking[Date]<=Tracking[[#This Row],[Date]]),(Tracking[Type]<>"Income")*(-1) + (Tracking[Type]="Income"))} -> 1371.9 | H49: {=IF(AND(Tracking[[#This Row],[Type]]="Income",shift_late_income_status="Active",DAY(Tracking[[#This Row],[Date]])>=shift_late_income_starting_day),DATE(YEAR(Tracking[[#This Row],[Date]]),MONTH(Tracking[[#This Row],[Date]])+1,1),Tracking[[#This Row],[Date]])} -> 46037
B50: 46037 | C50: Expenses | D50: Taxes | E50: 352.75 | G50: {=SUMPRODUCT(Tracking[Amount],--(Tracking[Date]<=Tracking[[#This Row],[Date]]),(Tracking[Type]<>"Income")*(-1) + (Tracking[Type]="Income"))} -> 1371.9 | H50: {=IF(AND(Tracking[[#This Row],[Type]]="Income",shift_late_income_status="Active",DAY(Tracking[[#This Row],[Date]])>=shift_late_income_starting_day),DATE(YEAR(Tracking[[#This Row],[Date]]),MONTH(Tracking[[#This Row],[Date]])+1,1),Tracking[[#This Row],[Date]])} -> 46037
B51: 46037 | C51: Expenses | D51: Benifits | E51: 102.38 | G51: {=SUMPRODUCT(Tracking[Amount],--(Tracking[Date]<=Tracking[[#This Row],[Date]]),(Tracking[Type]<>"Income")*(-1) + (Tracking[Type]="Income"))} -> 1371.9 | H51: {=IF(AND(Tracking[[#This Row],[Type]]="Income",shift_late_income_status="Active",DAY(Tracking[[#This Row],[Date]])>=shift_late_income_starting_day),DATE(YEAR(Tracking[[#This Row],[Date]]),MONTH(Tracking[[#This Row],[Date]])+1,1),Tracking[[#This Row],[Date]])} -> 46037
B52: 46037 | C52: Savings | D52: 401K | E52: 381.25 | G52: {=SUMPRODUCT(Tracking[Amount],--(Tracking[Date]<=Tracking[[#This Row],[Date]]),(Tracking[Type]<>"Income")*(-1) + (Tracking[Type]="Income"))} -> 1371.9 | H52: {=IF(AND(Tracking[[#This Row],[Type]]="Income",shift_late_income_status="Active",DAY(Tracking[[#This Row],[Date]])>=shift_late_income_starting_day),DATE(YEAR(Tracking[[#This Row],[Date]]),MONTH(Tracking[[#This Row],[Date]])+1,1),Tracking[[#This Row],[Date]])} -> 46037
B53: 46037 | C53: Expenses | D53: Taxes | E53: 13.44 | G53: {=SUMPRODUCT(Tracking[Amount],--(Tracking[Date]<=Tracking[[#This Row],[Date]]),(Tracking[Type]<>"Income")*(-1) + (Tracking[Type]="Income"))} -> 1371.9 | H53: {=IF(AND(Tracking[[#This Row],[Type]]="Income",shift_late_income_status="Active",DAY(Tracking[[#This Row],[Date]])>=shift_late_income_starting_day),DATE(YEAR(Tracking[[#This Row],[Date]]),MONTH(Tracking[[#This Row],[Date]])+1,1),Tracking[[#This Row],[Date]])} -> 46037
...

Sheet Budget Dashboard
C2: Budget Dashboard | Y2: Budget Dashboard
AQ5: Year
AN6: Select the year to view --> | AQ6: Current Year
AQ8: Period
AN9: Select the period to view --> | AQ9: 36557
Y11: {="Breakdown - " & IF(selected_period="Total Year","Total Year",selected_period_display) & " " & selected_year} -> Breakdown - February 2026 | AF11: Summary
C12: row_id | D12: header_row_id | E12: is_header | F12: is_cat | G12: is_total | H12: is_empty | I12: type | J12: item | K12: tracked | L12: budget | M12: sort_min_row | N12: sort_max_row | O12: tracked_range | P12: tracked_rank | Q12: budget_range | R12: budget_rank | S12: comb_rank | T12: comb_rank_range | U12: comb_rank_norm | V12: comb_rank_norm_run_range | W12: comb_rank_unique | X12: sorted_row_id [Lookup]
C13: {=income_header_row} -> 9 | D13: =IF(is_header,row_id, IF(NOT(is_empty),D12,-1)) -> 9 | E13: {=1*OR(row_id=income_header_row,row_id=expenses_header_row,row_id=savings_header_row)} -> 1 | F13: =1*NOT(OR(E13,G13,H13)) -> 0 | G13: {=OR(row_id=income_total_row,row_id=expenses_total_row,row_id=savings_total_row)*1} -> 0 | H13: =1*OR(row_id="/1",row_id="/2",row_id=-1) -> 0 | I13: {=IFERROR(INDEX('Budget Planning'!C:C,header_row_id),"")} -> Income | J13: {=IFERROR(INDEX('Budget Planning'!C:C,row_id),"")} -> Income | K13: {=IF(OR(is_empty,is_header),"", IF(is_total, IF(selected_period="Total Year", SUM(Tracking[Amount] * (Tracking[Type]=type) * (YEAR(Tracking[Effective Date])=selected_year)), SUM(Tracking[Amount] * (Tracking[Type]=type) * (YEAR(Tracking[Effective Date])=selected_year) * (MONTH(Tracking[Effective Date])=selected_period))), IF(selected_period="Total Year", SUM(Tracking[Amount] * (Tracking[Type]=type) * (Tracking[Category]=item) * (YEAR(Tracking[Effective Date])=selected_year)), SUM(Tracking[Amount] * (Tracking[Type]=type) * (Tracking[Category]=item) * (YEAR(Tracking[Effective Date])=selected_year) * (MONTH(Tracking[Effective Date])=selected_period))) ))} | L13: {=IF(OR(is_header,is_empty),"", INDEX('Budget Planning'!$E:$CI,row_id, MATCH(IF(selected_period="Total Year",selected_year,DATE(selected_year,selected_period,1)),'Budget Planning'!$E$9:$CI$9,0)))} | M13: {=IF(is_cat, IF(header_row_id=income_header_row,MATCH(income_min_row,$C:$C,0), IF(header_row_id=expenses_header_row,MATCH(expenses_min_row,$C:$C,0), IF(header_row_id=savings_header_row,MATCH(savings_min_row,$C:$C,0),""))),"")} | N13: {=IF(is_cat, IF(header_row_id=income_header_row,MATCH(income_max_row,$C:$C,0), IF(header_row_id=expenses_header_row,MATCH(expenses_max_row,$C:$C,0), IF(header_row_id=savings_header_row,MATCH(savings_max_row,$C:$C,0),""))),"")} | O13: =IF(is_cat,ADDRESS(sort_min_row,COLUMN(tracked)) & ":" & ADDRESS(sort_max_row,COLUMN(tracked)),"") | P13: =IF(is_cat,RANK(tracked,INDIRECT(tracked_range),0),"") | Q13: =IF(is_cat,ADDRESS(sort_min_row,COLUMN(budget)) & ":" & ADDRESS(sort_max_row,COLUMN(budget)),"") | R13: =IF(is_cat,RANK(budget,INDIRECT(budget_range),0),"") | S13: =IF(is_cat,_xlfn.NUMBERVALUE(tracked_rank & budget_rank),"") | T13: =IF(is_cat,ADDRESS(sort_min_row,COLUMN(comb_rank)) & ":" & ADDRESS(sort_max_row,COLUMN(comb_rank)),"") | U13: =IF(is_cat,RANK(comb_rank,INDIRECT(comb_rank_range),1),"") | V13: =IF(is_cat,ADDRESS(sort_min_row,COLUMN(comb_rank_norm)) & ":" & ADDRESS(ROW(),COLUMN(comb_rank_norm)),"") | W13: =IF(is_cat,comb_rank_norm + COUNTIF(INDIRECT(comb_rank_norm_run_range),comb_rank_norm)-1,"") | X13: =IF(is_cat,header_row_id + comb_rank_unique,row_id) -> 9 | Y13: =IF(is_empty,"",INDEX(J:J,MATCH(row_id,$X:$X,0))) -> Income | Z13: =IF(is_empty,"",IF(is_header,"Tracked",INDEX($K:$K,MATCH(row_id,$X:$X,0)))) -> Tracked | AA13: =IF(is_empty,"",IF(is_header,"Budget",INDEX($L:$L,MATCH(row_id,$X:$X,0)))) -> Budget | AB13: =IF(is_empty,"",IF(is_header,"% Compl",IFERROR(out_tracked/out_budget,"-"))) -> % Compl | AC13: =IF(is_empty,"",IF(is_header,"Remaining",IF(out_budget-out_tracked>0,out_budget-out_tracked,0))) -> Remaining | AD13: =IF(is_empty,"",IF(is_header,"Excess",IF(out_budget-out_tracked<0,out_tracked-out_budget,0))) -> Excess
